<?xml version='1.0'?>

<robot name="localization" xmlns:xacro="http://www.ros.org/wiki/xacro">
 <xacro:include filename="$(find localization)/urdf/robot.gazebo" />
  
  <link name="base_footprint" />  

  <material name="blue">
    <color rgba="0 0 0.8 1" />
  </material>	


<!-- ..................base link.................. -->

  <joint name="bae_footprint_joint" type="fixed">
    <origin xyz="0 0 0" rpy="0 0 0" />
    <parent link="base_footprint"/>
    <child link="base_link" />
  </joint>

  <link name='base_link'>
    <pose>0 0 0.1 0 0 0</pose>

    <inertial>
      <mass value="15.0"/>
      <origin xyz="0.0 0 0" rpy=" 0 0 0"/>
      <inertia
          ixx="0.1" ixy="0" ixz="0"
          iyy="0.1" iyz="0"
          izz="0.1"
      />
    </inertial>

    <collision name='collision'>
      <origin xyz="0 0 0" rpy=" 0 0 0"/> 
      <geometry>
        <box size=".4 .2 .1"/>
      </geometry>
    </collision>

    <visual name='base_link_visual'>
      <origin xyz="0 0 0" rpy=" 0 0 0"/>
      <geometry>
        <box size=".4 .2 .1"/>
      </geometry>
      <material name="blue"/>
    </visual>


    <collision name='back_caster_collision'>
      <origin xyz="-0.15 0 -0.05" rpy=" 0 0 0"/>
      <geometry>
        <sphere radius="0.0499"/>
      </geometry>
    </collision>

    <visual name='back_caster_visual'>
      <origin xyz="-0.15 0 -0.05" rpy=" 0 0 0"/>
      <geometry>
        <sphere radius="0.05"/>
      </geometry>
    </visual>

    <collision name='front_caster_collision'>
      <origin xyz="0.15 0 -0.05" rpy=" 0 0 0"/>
      <geometry>
        <sphere radius="0.0499"/>
      </geometry>
    </collision>

    <visual name='front_caster_visual'>
      <origin xyz="0.15 0 -0.05" rpy=" 0 0 0"/>
      <geometry>
        <sphere radius="0.05"/>
      </geometry>
    </visual>

  </link>
<!-- ..................left wheel link.................. -->

  <link name="left_wheel">
    <inertial>
      <origin xyz="0 0 0" rpy=" 0 .1 .1"/>
      <mass value="5.0"/>
      <inertia
	ixx="0.1" ixy="0" ixz="0"
	iyy="0.1" iyz="0"
	izz="0.1"
      />
    </inertial>

    <collision name='collision'>
      <origin xyz="0 0 0" rpy=" 0 1.5707 1.5707"/>
      <geometry>
        <cylinder  radius="0.1" length="0.05"/>
      </geometry>
    </collision>
	
    <visual name='left_wheel_visual'>
      <origin xyz="0 0 0" rpy=" 0 1.5707 1.5707"/>
      <geometry>
        <cylinder  radius="0.1" length="0.05"/>
      </geometry>
      <material name="blue"/>
    </visual>
		
  </link>

  <joint type="continuous" name="left_wheel_hinge">
    <origin xyz="0 0.15 0" rpy="0 0 0"/>
    <child link="left_wheel"/>
    <parent link="base_link"/>
    <axis xyz="0 1 0" rpy="0 0 0"/>
    <limit effort="10000" velocity="1000"/>
    <dynamics damping="1.0" friction="1.0"/>
  </joint>

<!-- ..................right wheel link.................. -->

  <link name="right_wheel">
    <inertial>
     <origin xyz="0 0 0" rpy=" 0 1.5707 1.5707"/>
     <mass value="5.0"/>
     <inertia
       ixx="0.1" ixy="0" ixz="0"
       iyy="0.1" iyz="0"
       izz="0.1"
      />
    </inertial>

    <collision name='collision'>
      <origin xyz="0 0 0" rpy=" 0 1.5707 1.5707"/>
      <geometry>
        <cylinder  radius="0.1" length="0.05"/>
      </geometry>
    </collision>
	
    <visual name='right_wheel_visual'>
      <origin xyz="0 0 0" rpy=" 0 1.5707 1.5707"/>
      <geometry>
        <cylinder  radius="0.1" length="0.05"/>
      </geometry>
      <material name="blue"/>
    </visual>
		
   </link>

   <joint type="continuous" name="right_wheel_hinge">
    <origin xyz="0 -0.15 0" rpy=" 0 0 0"/>
    <child link="right_wheel"/>
    <parent link="base_link"/>
    <axis xyz="0 1 0" rpy=" 0 0 0"/>
    <limit effort="10000" velocity="1000"/>
    <dynamics damping="1.0" friction="1.0"/>
   </joint>

<!-- ..................camera joint link.................. -->

   <link name="left_camera">
     <inertial>
	<origin xyz="0 0 0" rpy=" 0 0 0" />
	<mass value="0.1"	/>
	<inertia
	  ixx="1e-6" ixy="0" ixz="0"
	  iyy="1e-6" iyz="0"
	  izz="1e-6"
	  />
     </inertial>

     <collision>
	<origin xyz="0 0 0" rpy=" 0 0 0" />
	<geometry>
	<box size="0.05 0.05 0.05"/>
	</geometry>
     </collision>
	
     <visual>
      <origin xyz="0 0 0" rpy=" 0 0 0" />
      <geometry>
	    <box size="0.05 0.05 0.05"/>
      </geometry>

     </visual>
	
    </link>
	
    <joint type="fixed" name="left_camera_joint">
	<origin xyz="0.2 0 0" rpy=" 0 0 0" />
	<child  link="left_camera"/>
	<parent	link="base_link"/>
    </joint>

<!--

     <link name="right_camera">
     <inertial>
	<origin xyz="0 0 0" rpy=" 0 0 0" />
	<mass value="0.1"	/>
	<inertia
	  ixx="1e-6" ixy="0" ixz="0"
	  iyy="1e-6" iyz="0"
	  izz="1e-6"
	  />
     </inertial>

     <collision>
	<origin xyz="0 0 0" rpy=" 0 0 0" />
	<geometry>
	<box size="0.05 0.05 0.05"/>
	</geometry>
     </collision>
	
     <visual>
      <origin xyz="0 0 0" rpy=" 0 0 0" />
      <geometry>
	    <box size="0.05 0.05 0.05"/>
      </geometry>
      <material name="blue" />	
     </visual>
	
    </link>
	
    <joint type="fixed" name="right_camera_joint">
	<origin xyz="0.2 -.04 0" rpy=" 0 0 0" />
	<child  link="right_camera"/>
	<parent	link="chassis"/>
    </joint>	
-->

<!-- ..................imu sensor link.................. -->

    <link name="imu_sensor">
       <inertial>
        <origin xyz="0 0 0" rpy=" 0 0 0" />
        <mass value="0.01" />
        <inertia
	  ixx="0.00000015" ixy="0" ixz="0"
	  iyy="0.00000015" iyz="0"
	  izz="0.00000015"
	  />
	</inertial>
		
	<collision>
    	 <origin xyz="0 0 0" rpy=" 0 0 0" />
	 <geometry>
	   <box size="0.02 0.02 0.02"/>
	 </geometry>
	</collision>
	
	<visual>
          <origin xyz="0 0 0" rpy=" 0 0 0" />
	  <geometry>
	    <box size="0.02 0.02 0.02"/>
	  </geometry>
	</visual>

      </link>

      <joint type="fixed" name="imu_sensor_joint">
	<axis xyz="1 0 0" rpy=" 0 0 0" />
	<origin xyz="0 0 0.07" />
	<child  link="imu_sensor"/>
	<parent	link="base_link"/>
      </joint>

<!-- ..................gps sensor link.................. -->

	<link name="GPS_sensor">
       <inertial>
        <origin xyz="0 0 0" rpy=" 0 0 0" />
        <mass value="0.01" />
        <inertia
	  ixx="0.00000015" ixy="0" ixz="0"
	  iyy="0.00000015" iyz="0"
	  izz="0.00000015"
	  />
	</inertial>
		
	<collision>
    	 <origin xyz="0 0 0" rpy=" 0 0 0" />
	 <geometry>
	   <box size="0.02 0.02 0.02"/>
	 </geometry>
	</collision>
	
	<visual>
          <origin xyz="0 0 0" rpy=" 0 0 0" />
	  <geometry>
	    <box size="0.02 0.02 0.02"/>
	  </geometry>
	</visual>

      </link>

      <joint type="fixed" name="GPS_sensor_joint">
	<axis xyz="1 0 0" rpy=" 0 0 0" />
	<origin xyz="0.08 0 0.07" />
	<child  link="GPS_sensor"/>
	<parent	link="base_link"/>
      </joint>
		
		
    
</robot>

